Workbook

Sheet new total list
A1: Name+ company | B1: {=IF(ISBLANK(C1:C1845), "", TRIM(C1:C1845 & " " & D1:D1845))} -> Name1 Name 2 | C1: Name1 | D1: Name 2 | E1: mail | F1: company | G1: type | H1: connection | I1: 2nd | J1: Code | K1: Invite | L1: Save the date MTS 26 | M1: Registered check: ARRAYFORMULA(IF(ISNUMBER(MATCH(LOWER(TRIM(E455:E1201)),LOWER(TRIM(#REF!)), 0)), TRUE, FALSE)) | N1: =VLOOKUP(B1,'MTS 2026 registrations'!A:A,1,false) -> #N/A
A2: =B2&" "&F2 -> Aabharan Hemanth Myst Works | B2: Aabharan Hemanth | C2: Aabharan | D2: Hemanth | E2: aabharan@myst.works | F2: Myst Works | G2: Startup/founder | H2: Radena Tsoneva (YES!Delft) | J2: HNX9C7 | K2: Free | L2: Bounce | M2: =VLOOKUP(E2,'MTS 2026 registrations'!B:B,1,false) -> #N/A | N2: =VLOOKUP(B2,'MTS 2026 registrations'!A:A,1,false) -> #N/A | O2: =IF(AND(ISNA(M2), ISNA(N2)), "Marked", "") -> Marked
A3: =B3&" "&F3 -> Adnan Tunovic Mungosworks | B3: Adnan Tunovic | C3: Adnan | D3: Tunovic | E3: adnan@mungosworks.nl | F3: Mungosworks | G3: Startup/founder | H3: Radena Tsoneva (YES!Delft) | J3: XGFIJJ | K3: Free | L3: Bounce | M3: =VLOOKUP(E3,'MTS 2026 registrations'!B:B,1,false) -> #N/A | N3: =VLOOKUP(B3,'MTS 2026 registrations'!A:A,1,false) -> #N/A | O3: =IF(AND(ISNA(M3), ISNA(N3)), "Marked", "") -> Marked
A4: =B4&" "&F4 -> Ahmed Mohamedali conical | B4: Ahmed Mohamedali | C4: Ahmed | D4: Mohamedali | E4: ahmed@conical.ai | F4: conical | G4: Startup/founder | H4: Radena Tsoneva (YES!Delft) | J4: IQNFNA | K4: Free | L4: Bounce | M4: =VLOOKUP(E4,'MTS 2026 registrations'!B:B,1,false) -> #N/A | N4: =VLOOKUP(B4,'MTS 2026 registrations'!A:A,1,false) -> #N/A | O4: =IF(AND(ISNA(M4), ISNA(N4)), "Marked", "") -> Marked
A5: =B5&" "&F5 -> Ahmed Faramawy Infinipipe | B5: Ahmed Faramawy | C5: Ahmed | D5: Faramawy | E5: ahmed@infinipipe.com | F5: Infinipipe | G5: Startup/founder | H5: Radena Tsoneva (YES!Delft) | J5: PW4TW4 | K5: Free | L5: Bounce | M5: =VLOOKUP(E5,'MTS 2026 registrations'!B:B,1,false) -> #N/A | N5: =VLOOKUP(B5,'MTS 2026 registrations'!A:A,1,false) -> #N/A | O5: =IF(AND(ISNA(M5), ISNA(N5)), "Marked", "") -> Marked
A6: =B6&" "&F6 -> Akarsh Gopal Myst Works | B6: Akarsh Gopal | C6: Akarsh | D6: Gopal | E6: akarsh@myst.works | F6: Myst Works | G6: Startup/founder | H6: Radena Tsoneva (YES!Delft) | J6: H9N5CZ | K6: Free | L6: Bounce | M6: =VLOOKUP(E6,'MTS 2026 registrations'!B:B,1,false) -> #N/A | N6: =VLOOKUP(B6,'MTS 2026 registrations'!A:A,1,false) -> #N/A | O6: =IF(AND(ISNA(M6), ISNA(N6)), "Marked", "") -> Marked
A7: =B7&" "&F7 -> Akash Parmesar olympian | B7: Akash Parmesar | C7: Akash | D7: Parmesar | E7: akash@olympian.ai | F7: olympian | G7: Startup/founder | H7: Radena Tsoneva (YES!Delft) | J7: L362K9 | K7: Free | L7: Bounce | M7: =VLOOKUP(E7,'MTS 2026 registrations'!B:B,1,false) -> #N/A | N7: =VLOOKUP(B7,'MTS 2026 registrations'!A:A,1,false) -> #N/A | O7: =IF(AND(ISNA(M7), ISNA(N7)), "Marked", "") -> Marked
A8: =B8&" "&F8 -> Amir Piltan sporebi | B8: Amir Piltan | C8: Amir | D8: Piltan | E8: amir@sporebi.com | F8: sporebi | G8: Startup/founder | H8: Radena Tsoneva (YES!Delft) | J8: 18ZZQ3 | K8: Free | L8: Bounce | M8: =VLOOKUP(E8,'MTS 2026 registrations'!B:B,1,false) -> #N/A | N8: =VLOOKUP(B8,'MTS 2026 registrations'!A:A,1,false) -> #N/A | O8: =IF(AND(ISNA(M8), ISNA(N8)), "Marked", "") -> Marked
A9: =B9&" "&F9 -> Andre Cossee Anything Connected | B9: Andre Cossee | C9: Andre | D9: Cossee | E9: andre@anything-connected.com | F9: Anything Connected | G9: Startup/founder | H9: Radena Tsoneva (YES!Delft) | J9: YAHJSA | K9: Free | L9: Bounce | M9: =VLOOKUP(E9,'MTS 2026 registrations'!B:B,1,false) -> #N/A | N9: =VLOOKUP(B9,'MTS 2026 registrations'!A:A,1,false) -> #N/A | O9: =IF(AND(ISNA(M9), ISNA(N9)), "Marked", "") -> Marked
A10: =B10&" "&F10 -> Andreas Schmidt-Ott tudelft | B10: Andreas Schmidt-Ott | C10: Andreas | D10: Schmidt-Ott | E10: a.schmidt-ott@tudelft.nl | F10: tudelft | G10: Startup/founder | H10: Radena Tsoneva (YES!Delft) | J10: 352ASR | K10: Free | L10: Bounce | M10: =VLOOKUP(E10,'MTS 2026 registrations'!B:B,1,false) -> #N/A | N10: =VLOOKUP(B10,'MTS 2026 registrations'!A:A,1,false) -> #N/A | O10: =IF(AND(ISNA(M10), ISNA(N10)), "Marked", "") -> Marked
A11: =B11&" "&F11 -> Angelique Nederlof rdgg | B11: Angelique Nederlof | C11: Angelique | D11: Nederlof | E11: angelique.nederlof@rdgg.nl | F11: rdgg | G11: Mentor/Expert | H11: Radena Tsoneva (YES!Delft) | J11: XBDDWW | K11: Free | L11: Bounce | M11: =VLOOKUP(E11,'MTS 2026 registrations'!B:B,1,false) -> #N/A | N11: =VLOOKUP(B11,'MTS 2026 registrations'!A:A,1,false) -> #N/A | O11: =IF(AND(ISNA(M11), ISNA(N11)), "Marked", "") -> Marked
A12: =B12&" "&F12 -> Anthony Thirkettle giaura | B12: Anthony Thirkettle | C12: Anthony | D12: Thirkettle | E12: anthony@giaura.com | F12: giaura | G12: Startup/founder | H12: Radena Tsoneva (YES!Delft) | J12: BBGHLD | K12: Free | L12: Bounce | M12: =VLOOKUP(E12,'MTS 2026 registrations'!B:B,1,false) -> #N/A | N12: =VLOOKUP(B12,'MTS 2026 registrations'!A:A,1,false) -> #N/A | O12: =IF(AND(ISNA(M12), ISNA(N12)), "Marked", "") -> Marked
A13: =B13&" "&F13 -> Arjan Oudshoorn delftab | B13: Arjan Oudshoorn | C13: Arjan | D13: Oudshoorn | E13: oudshoorn@delftab.com | F13: delftab | G13: Startup/founder | H13: Radena Tsoneva (YES!Delft) | J13: 5QSHU1 | K13: Free | L13: Bounce | M13: =VLOOKUP(E13,'MTS 2026 registrations'!B:B,1,false) -> #N/A | N13: =VLOOKUP(B13,'MTS 2026 registrations'!A:A,1,false) -> #N/A | O13: =IF(AND(ISNA(M13), ISNA(N13)), "Marked", "") -> Marked
... A24: =B24&" "&F24 -> Chandler hatton SimGas | B24: Chandler hatton | C24: Chandler | D24: hatton | E24: chandlerhatton@simgas.org | F24: SimGas | G24: Startup/founder | H24: Radena Tsoneva (YES!Delft) | J24: YA76QZ | K24: Free | L24: Bounce | M24: =VLOOKUP(E24,'MTS 2026 registrations'!B:B,1,false) -> #N/A | N24: =VLOOKUP(B24,'MTS 2026 registrations'!A:A,1,false) -> #N/A | O24: =IF(AND(ISNA(M24), ISNA(N24)), "Marked", "") -> Marked
A25: =B25&" "&F25 -> Chris van Voorden innovationquarter | B25: Chris van Voorden | C25: Chris | D25: van Voorden | E25: chris.vanvoorden@innovationquarter.nl | F25: innovationquarter | G25: Partner | H25: Freek Smoes (YES!Delft) | I25: Horizon Flevoland | K25: NO | L25: Bounce | M25: =VLOOKUP(E25,'MTS 2026 registrations'!B:B,1,false) -> #N/A | N25: =VLOOKUP(B25,'MTS 2026 registrations'!A:A,1,false) -> #N/A | O25: =IF(AND(ISNA(M25), ISNA(N25)), "Marked", "") -> Marked
A26: =B26&" "&F26 -> Christiaan van Nispen tilercharge | B26: Christiaan van Nispen | C26: Christiaan | D26: van Nispen | E26: christiaan@tilercharge.com | F26: tilercharge | G26: Startup/founder | H26: Radena Tsoneva (YES!Delft) | J26: U9XMLU | K26: Free | L26: Bounce | M26: =VLOOKUP(E26,'MTS 2026 registrations'!B:B,1,false) -> #N/A | N26: =VLOOKUP(B26,'MTS 2026 registrations'!A:A,1,false) -> #N/A | O26: =IF(AND(ISNA(M26), ISNA(N26)), "Marked", "") -> Marked
A27: =B27&" "&F27 -> Christopher Arida diwama | B27: Christopher Arida | C27: Christopher | D27: Arida | E27: christopherarida@diwama.com | F27: diwama | G27: Startup/founder | H27: Radena Tsoneva (YES!Delft) | J27: ZCFNB9 | K27: Free | L27: Bounce | M27: =VLOOKUP(E27,'MTS 2026 registrations'!B:B,1,false) -> #N/A | N27: =VLOOKUP(B27,'MTS 2026 registrations'!A:A,1,false) -> #N/A | O27: =IF(AND(ISNA(M27), ISNA(N27)), "Marked", "") -> Marked
A28: =B28&" "&F28 -> Claire Bénard merqato | B28: Claire Bénard | C28: Claire | D28: Bénard | E28: claire@merqato.eu | F28: merqato | G28: Startup/founder | H28: Radena Tsoneva (YES!Delft) | J28: P4ZPMZ | K28: Free | L28: Bounce | M28: =VLOOKUP(E28,'MTS 2026 registrations'!B:B,1,false) -> #N/A | N28: =VLOOKUP(B28,'MTS 2026 registrations'!A:A,1,false) -> #N/A | O28: =IF(AND(ISNA(M28), ISNA(N28)), "Marked", "") -> Marked
A29: =B29&" "&F29 -> Daan Protension Composites | B29: Daan | C29: Daan | E29: daan@protension.nl | F29: Protension Composites | G29: Startup/founder | H29: Radena Tsoneva (YES!Delft) | J29: 5Z7I83 | K29: Free | L29: Bounce | M29: =VLOOKUP(E29,'MTS 2026 registrations'!B:B,1,false) -> #N/A | N29: =VLOOKUP(B29,'MTS 2026 registrations'!A:A,1,false) -> #N/A | O29: =IF(AND(ISNA(M29), ISNA(N29)), "Marked", "") -> Marked
A30: =B30&" "&F30 -> Daniël van den Bosch vibestechnology | B30: Daniël van den Bosch | C30: Daniël | D30: van den Bosch | E30: daniel@vibestechnology.com | F30: vibestechnology | G30: Startup/founder | H30: Radena Tsoneva (YES!Delft) | J30: 1137HG | K30: Free | L30: Bounce | M30: =VLOOKUP(E30,'MTS 2026 registrations'!B:B,1,false) -> #N/A | N30: =VLOOKUP(B30,'MTS 2026 registrations'!A:A,1,false) -> #N/A | O30: =IF(AND(ISNA(M30), ISNA(N30)), "Marked", "") -> Marked
A31: =B31&" "&F31 -> Dennis Saaltink CheckZis | B31: Dennis Saaltink | C31: Dennis | D31: Saaltink | E31: dennis@checkzis.com | F31: CheckZis | G31: Startup/founder | H31: Radena Tsoneva (YES!Delft) | J31: WSBHKJ | K31: Free | L31: Bounce | M31: =VLOOKUP(E31,'MTS 2026 registrations'!B:B,1,false) -> #N/A | N31: =VLOOKUP(B31,'MTS 2026 registrations'!A:A,1,false) -> #N/A | O31: =IF(AND(ISNA(M31), ISNA(N31)), "Marked", "") -> Marked
A32: =B32&" "&F32 -> Dirk Dokter atmosuav | B32: Dirk Dokter | C32: Dirk | D32: Dokter | E32: dirk.dokter@atmosuav.com | F32: atmosuav | G32: Startup/founder | H32: Radena Tsoneva (YES!Delft) | J32: C8IZUC | K32: Free | L32: Bounce | M32: =VLOOKUP(E32,'MTS 2026 registrations'!B:B,1,false) -> #N/A | N32: =VLOOKUP(B32,'MTS 2026 registrations'!A:A,1,false) -> #N/A | O32: =IF(AND(ISNA(M32), ISNA(N32)), "Marked", "") -> Marked
A33: =B33&" "&F33 -> E. Geertsema antoniusziekenhuis | B33: E. Geertsema | C33: E. | D33: Geertsema | E33: e.geertsema@antoniusziekenhuis.nl | F33: antoniusziekenhuis | G33: Corporate | H33: Moshe Sijben (YES!Delft) | K33: NO | L33: Bounce | M33: =VLOOKUP(E33,'MTS 2026 registrations'!B:B,1,false) -> #N/A | N33: =VLOOKUP(B33,'MTS 2026 registrations'!A:A,1,false) -> #N/A | O33: =IF(AND(ISNA(M33), ISNA(N33)), "Marked", "") -> Marked
A34: =B34&" "&F34 -> Eduard Ijsselmuiden delftdynamics | B34: Eduard Ijsselmuiden | C34: Eduard | D34: Ijsselmuiden | E34: e.g.ijsselmuiden@delftdynamics.nl | F34: delftdynamics | G34: Startup/founder | H34: Radena Tsoneva (YES!Delft) | J34: B3KMTG | K34: Free | L34: Bounce | M34: =VLOOKUP(E34,'MTS 2026 registrations'!B:B,1,false) -> #N/A | N34: =VLOOKUP(B34,'MTS 2026 registrations'!A:A,1,false) -> #N/A | O34: =IF(AND(ISNA(M34), ISNA(N34)), "Marked", "") -> Marked
A35: =B35&" "&F35 -> Eldert Besseling campusatsea | B35: Eldert Besseling | C35: Eldert | D35: Besseling | E35: eldert.besseling@campusatsea.nl | F35: campusatsea | G35: Startup Ecosystem | H35: Moshe Sijben (YES!Delft) | K35: NO | L35: Bounce | M35: =VLOOKUP(E35,'MTS 2026 registrations'!B:B,1,false) -> #N/A | N35: =VLOOKUP(B35,'MTS 2026 registrations'!A:A,1,false) -> #N/A | O35: =IF(AND(ISNA(M35), ISNA(N35)), "Marked", "") -> Marked
A36: =B36&" "&F36 -> Emil Hernandez Renset bv | B36: Emil Hernandez | C36: Emil | D36: Hernandez | E36: emil@renset.nl | F36: Renset bv | G36: Startup/founder | H36: Radena Tsoneva (YES!Delft) | J36: QWCAL0 | K36: Free | L36: Bounce | M36: =VLOOKUP(E36,'MTS 2026 registrations'!B:B,1,false) -> #N/A | N36: =VLOOKUP(B36,'MTS 2026 registrations'!A:A,1,false) -> #N/A | O36: =IF(AND(ISNA(M36), ISNA(N36)), "Marked", "") -> Marked
A37: =B37&" "&F37 -> Ernesto Mobbr Crowd Payment | B37: Ernesto | C37: Ernesto | E37: ernesto@mobbr.com | F37: Mobbr Crowd Payment | G37: Startup/founder | H37: Radena Tsoneva (YES!Delft) | J37: K4CQ7T | K37: Free | L37: Bounce | M37: =VLOOKUP(E37,'MTS 2026 registrations'!B:B,1,false) -> #N/A | N37: =VLOOKUP(B37,'MTS 2026 registrations'!A:A,1,false) -> #N/A | O37: =IF(AND(ISNA(M37), ISNA(N37)), "Marked", "") -> Marked
A38: =B38&" "&F38 -> Esther Zandvliet arnold-siedsma | B38: Esther Zandvliet | C38: Esther | D38: Zandvliet | E38: ezandvliet@arnold-siedsma.nl | F38: arnold-siedsma | G38: Partner | H38: Radena Tsoneva (YES!Delft) | J38: XCK3K7 | K38: Free | L38: Bounce | M38: =VLOOKUP(E38,'MTS 2026 registrations'!B:B,1,false) -> #N/A | N38: =VLOOKUP(B38,'MTS 2026 registrations'!A:A,1,false) -> #N/A | O38: =IF(AND(ISNA(M38), ISNA(N38)), "Marked", "") -> Marked
A39: =B39&" "&F39 -> Evgeny EVI Safety Technology | B39: Evgeny | C39: Evgeny | E39: eshavlyugin@evist.ai | F39: EVI Safety Technology | G39: Startup/founder | H39: Pablo Benéitez (YES!Delft) | J39: O85TDB | K39: Free | L39: Bounce | M39: =VLOOKUP(E39,'MTS 2026 registrations'!B:B,1,false) -> #N/A | N39: =VLOOKUP(B39,'MTS 2026 registrations'!A:A,1,false) -> #N/A | O39: =IF(AND(ISNA(M39), ISNA(N39)), "Marked", "") -> Marked
A40: =B40&" "&F40 -> Finn Boonman olympian | B40: Finn Boonman | C40: Finn | D40: Boonman | E40: finn@olympian.ai | F40: olympian | G40: Startup/founder | H40: Radena Tsoneva (YES!Delft) | J40: U8YT8B | K40: Free | L40: Bounce | M40: =VLOOKUP(E40,'MTS 2026 registrations'!B:B,1,false) -> #N/A | N40: =VLOOKUP(B40,'MTS 2026 registrations'!A:A,1,false) -> #N/A | O40: =IF(AND(ISNA(M40), ISNA(N40)), "Marked", "") -> Marked
A41: =B41&" "&F41 -> Florent Gatin kien | B41: Florent Gatin | C41: Florent | D41: Gatin | E41: florent@kien.io | F41: kien | G41: Startup/founder | H41: Radena Tsoneva (YES!Delft) | J41: PBKKDX | K41: Free | L41: Bounce | M41: =VLOOKUP(E41,'MTS 2026 registrations'!B:B,1,false) -> #N/A | N41: =VLOOKUP(B41,'MTS 2026 registrations'!A:A,1,false) -> #N/A | O41: =IF(AND(ISNA(M41), ISNA(N41)), "Marked", "") -> Marked
A42: =B42&" "&F42 -> Frank van der Ent tribess | B42: Frank van der Ent | C42: Frank | D42: van der Ent | E42: frank.vanderent@tribess.com | F42: tribess | G42: Startup/founder | H42: Radena Tsoneva (YES!Delft) | J42: 47QEXY | K42: Free | L42: Bounce | M42: =VLOOKUP(E42,'MTS 2026 registrations'!B:B,1,false) -> #N/A | N42: =VLOOKUP(B42,'MTS 2026 registrations'!A:A,1,false) -> #N/A | O42: =IF(AND(ISNA(M42), ISNA(N42)), "Marked", "") -> Marked
A43: =B43&" "&F43 -> Gerrit Jan Van 't Veen Mills, Clay and Carpenter | B43: Gerrit Jan Van 't Veen | C43: Gerrit Jan | D43: Van 't Veen | E43: gj@dutchcoastsoftware.com | F43: Mills, Clay and Carpenter | G43: Startup/founder | H43: Radena Tsoneva (YES!Delft) | J43: R9NC86 | K43: Free | L43: Bounce | M43: =VLOOKUP(E43,'MTS 2026 registrations'!B:B,1,false) -> #N/A | N43: =VLOOKUP(B43,'MTS 2026 registrations'!A:A,1,false) -> #N/A | O43: =IF(AND(ISNA(M43), ISNA(N43)), "Marked", "") -> Marked
A44: =B44&" "&F44 -> Gunawan Kusuma 4FOLD (Holland Container Innovations) | B44: Gunawan Kusuma | C44: Gunawan | D44: Kusuma | E44: g.kusuma@hcinnovations.nl | F44: 4FOLD (Holland Container Innovations) | G44: Startup/founder | H44: Radena Tsoneva (YES!Delft) | J44: IPM4WY | K44: Free | L44: Bounce | M44: =VLOOKUP(E44,'MTS 2026 registrations'!B:B,1,false) -> #N/A | N44: =VLOOKUP(B44,'MTS 2026 registrations'!A:A,1,false) -> #N/A | O44: =IF(AND(ISNA(M44), ISNA(N44)), "Marked", "") -> Marked
A45: =B45&" "&F45 -> Hans Cool alucha | B45: Hans Cool | C45: Hans | D45: Cool | E45: hans.cool@alucha.com | F45: alucha | G45: Mentor/Expert | H45: Radena Tsoneva (YES!Delft) | K45: NO | L45: Bounce | M45: =VLOOKUP(E45,'MTS 2026 registrations'!B:B,1,false) -> #N/A | N45: =VLOOKUP(B45,'MTS 2026 registrations'!A:A,1,false) -> #N/A | O45: =IF(AND(ISNA(M45), ISNA(N45)), "Marked", "") -> Marked
A46: =B46&" "&F46 -> Hein Willems Medvice Digital Health | B46: Hein Willems | C46: Hein | D46: Willems | E46: hein@medvice.io | F46: Medvice Digital Health | G46: Startup/founder | H46: Radena Tsoneva (YES!Delft) | J46: 388QUR | K46: Free | L46: Bounce | M46: =VLOOKUP(E46,'MTS 2026 registrations'!B:B,1,false) -> #N/A | N46: =VLOOKUP(B46,'MTS 2026 registrations'!A:A,1,false) -> #N/A | O46: =IF(AND(ISNA(M46), ISNA(N46)), "Marked", "") -> Marked
A47: =B47&" "&F47 -> Helen Nofrina focalyse | B47: Helen Nofrina | C47: Helen | D47: Nofrina | E47: helen.nofrina@focalyse.com | F47: focalyse | G47: Mentor/Expert | H47: Radena Tsoneva (YES!Delft) | K47: NO | L47: Bounce | M47: =VLOOKUP(E47,'MTS 2026 registrations'!B:B,1,false) -> #N/A | N47: =VLOOKUP(B47,'MTS 2026 registrations'!A:A,1,false) -> #N/A | O47: =IF(AND(ISNA(M47), ISNA(N47)), "Marked", "") -> Marked
A48: =B48&" "&F48 -> Henk Smith OCRS smithoverseas | B48: Henk Smith | C48: Henk | D48: Smith | E48: hjsmith@smithoverseas.com | F48: OCRS smithoverseas | G48: Startup/founder | H48: Radena Tsoneva (YES!Delft) | J48: GSL7EN | K48: Free | L48: Bounce | M48: =VLOOKUP(E48,'MTS 2026 registrations'!B:B,1,false) -> #N/A | N48: =VLOOKUP(B48,'MTS 2026 registrations'!A:A,1,false) -> #N/A | O48: =IF(AND(ISNA(M48), ISNA(N48)), "Marked", "") -> Marked
A49: =B49&" "&F49 -> Iris Schut rvo | B49: Iris Schut | C49: Iris | D49: Schut | E49: iris.schut@rvo.nl | F49: rvo | G49: Startup Ecosystem | H49: Radena Tsoneva (YES!Delft) | J49: GDKWUU | K49: Free | L49: Bounce | M49: =VLOOKUP(E49,'MTS 2026 registrations'!B:B,1,false) -> #N/A | N49: =VLOOKUP(B49,'MTS 2026 registrations'!A:A,1,false) -> #N/A | O49: =IF(AND(ISNA(M49), ISNA(N49)), "Marked", "") -> Marked
A50: =B50&" "&F50 -> Isaac Kargar supplyz | B50: Isaac Kargar | C50: Isaac | D50: Kargar | E50: isaac.kargar@supplyz.eu | F50: supplyz | G50: Startup/founder | H50: Radena Tsoneva (YES!Delft) | J50: T903PS | K50: Free | L50: Bounce | M50: =VLOOKUP(E50,'MTS 2026 registrations'!B:B,1,false) -> #N/A | N50: =VLOOKUP(B50,'MTS 2026 registrations'!A:A,1,false) -> #N/A | O50: =IF(AND(ISNA(M50), ISNA(N50)), "Marked", "") -> Marked
...

Sheet removed contacts
A1: Name+ company | B1: Name | C1: Name1 | D1: Name 2 | E1: mail | F1: company | G1: type | H1: connection | J1: Registered | K1: Invite | L1: Email 4 sent? | M1: Script check? | N1: Notes:
A2: =B2&" "&F2 -> Dieuwke Hoogland Female Ventures | B2: =C2&" "&D2 -> Dieuwke Hoogland | C2: Dieuwke | D2: Hoogland | E2: dieuwke@femaleventures.nl | F2: Female Ventures | G2: Startup Ecosystem | H2: Pablo Benéitez (YES!Delft) | K2: NO | L2: x | M2: NIET | O2: =vlookup(E2,Sheet16!B:C,1,false) -> #REF!
A3: =B3&" "&F3 -> Vera Hunter eur | B3: =C3&" "&D3 -> Vera Hunter | C3: Vera | D3: Hunter | E3: vera.hunter@eur.nl | F3: eur | G3: Education/research | H3: Moshe Sijben (YES!Delft) | J3: FALSE | K3: other job | L3: x | M3: Registered | O3: =vlookup(E3,Sheet16!B:C,1,false) -> #REF!
A4: =B4&" "&F4 -> Adrie Huesman shell | B4: =C4&" "&D4 -> Adrie Huesman | C4: Adrie | D4: Huesman | E4: adrie.huesman@shell.com | F4: shell | G4: Corporate | H4: Nannila Zevenhuizen (YES!Delft) | K4: NO | L4: NO | M4: NIET | O4: =vlookup(E4,Sheet16!B:C,1,false) -> #REF!
A5: =B5&" "&F5 -> Alkis Romeos shell | B5: =C5&" "&D5 -> Alkis Romeos | C5: Alkis | D5: Romeos | E5: alkis.romeos@shell.com | F5: shell | G5: Corporate | H5: Nannila Zevenhuizen (YES!Delft) | K5: NO | L5: NO | M5: NIET | O5: =vlookup(E5,Sheet16!B:C,1,false) -> #REF!
A6: =B6&" "&F6 -> Carola Berkouwer Rabobank | B6: =C6&" "&D6 -> Carola Berkouwer | C6: Carola | D6: Berkouwer | E6: Carola.Berkouwer@rabobank.nl | F6: Rabobank | G6: Partner | H6: Nannila Zevenhuizen (YES!Delft) | K6: NO | L6: NO | M6: Sent to Carola.Berkouwer@rabobank.nl on 2025-09-01 | O6: =vlookup(E6,Sheet16!B:C,1,false) -> #REF!
A7: =B7&" "&F7 -> Claire Rutteman Shell | B7: =C7&" "&D7 -> Claire Rutteman | C7: Claire | D7: Rutteman | E7: Claire.Rutteman@shell.com | F7: Shell | G7: Corporate | H7: Nannila Zevenhuizen (YES!Delft) | K7: NO | L7: NO | M7: Registered | O7: =vlookup(E7,Sheet16!B:C,1,false) -> #REF!
A8: =B8&" "&F8 -> Geert van de Wouw shell | B8: =C8&" "&D8 -> Geert van de Wouw | C8: Geert | D8: van de Wouw | E8: geert.vandewouw@shell.com | F8: shell | G8: Corporate | H8: Nannila Zevenhuizen (YES!Delft) | K8: NO | L8: NO | M8: NIET | O8: =vlookup(E8,Sheet16!B:C,1,false) -> #REF!
A9: =B9&" "&F9 -> Jaap Hulshoff duravermeer | B9: =C9&" "&D9 -> Jaap Hulshoff | C9: Jaap | D9: Hulshoff | E9: j.hulshoff@duravermeer.nl | F9: duravermeer | G9: Corporate | H9: Nannila Zevenhuizen (YES!Delft) | K9: NO | L9: NO | M9: Sent to j.hulshoff@duravermeer.nl on 2025-09-01 | O9: =vlookup(E9,Sheet16!B:C,1,false) -> #REF!
A10: =B10&" "&F10 -> Kiki de Vries yesdelftstudents | B10: =C10&" "&D10 -> Kiki de Vries | C10: Kiki | D10: de Vries | E10: kiki@yesdelftstudents.nl | F10: yesdelftstudents | G10: Startup Ecosystem | H10: Nannila Zevenhuizen (YES!Delft) | K10: NO | L10: NO | M10: NIET | O10: =vlookup(E10,Sheet16!B:C,1,false) -> #REF!
A11: =B11&" "&F11 -> Marcin Dukalski aramcooverseas | B11: =C11&" "&D11 -> Marcin Dukalski | C11: Marcin | D11: Dukalski | E11: marcin.dukalski@aramcooverseas.com | F11: aramcooverseas | G11: Partner | H11: Nannila Zevenhuizen (YES!Delft) | K11: NO | L11: NO | M11: NIET | O11: =vlookup(E11,Sheet16!B:C,1,false) -> #REF!
A12: =B12&" "&F12 -> Sayee Balaji shell | B12: =C12&" "&D12 -> Sayee Balaji | C12: Sayee | D12: Balaji | E12: sayee-prasaad.balaji@shell.com | F12: shell | G12: Corporate | H12: Nannila Zevenhuizen (YES!Delft) | K12: NO | L12: NO | M12: NIET | O12: =vlookup(E12,Sheet16!B:C,1,false) -> #REF!
A13: =B13&" "&F13 -> Sylvia Coenen Gemeente Delft | B13: =C13&" "&D13 -> Sylvia Coenen | C13: Sylvia | D13: Coenen | E13: scoenen@delft.nl | F13: Gemeente Delft | G13: Startup Ecosystem | H13: Nannila Zevenhuizen (YES!Delft) | K13: NO | L13: NO | M13: NIET | O13: =vlookup(E13,Sheet16!B:C,1,false) -> #REF!
A14: =B14&" "&F14 -> Unsal Evren shell | B14: =C14&" "&D14 -> Unsal Evren | C14: Unsal | D14: Evren | E14: evren.unsal@shell.com | F14: shell | G14: Corporate | H14: Nannila Zevenhuizen (YES!Delft) | K14: NO | L14: NO | M14: NIET | O14: =vlookup(E14,Sheet16!B:C,1,false) -> #REF!
A15: =B15&" "&F15 -> Wim Nobel rabobank | B15: =C15&" "&D15 -> Wim Nobel | C15: Wim | D15: Nobel | E15: wim.nobel@rabobank.nl | F15: rabobank | G15: Partner | H15: Ras Lalmy (YES!Delft) | J15: FALSE | K15: yes | L15: x | M15: NIET | O15: =vlookup(E15,Sheet16!B:C,1,false) -> #REF!
A16: =B16&" "&F16 -> Raf Koene innovationquarter | B16: =C16&" "&D16 -> Raf Koene | C16: Raf | D16: Koene | F16: innovationquarter | G16: Investor | H16: Jan Geert van Hall (YES!Delft) | K16: NO | L16: NO | M16: Does not work at IQ anymore | O16: =vlookup(E16,Sheet16!B:C,1,false) -> #REF!
A17: =B17&" "&F17 -> Jenny Konings tudelft | B17: =C17&" "&D17 -> Jenny Konings | C17: Jenny | D17: Konings | E17: j.j.m.konings@tudelft.nl | F17: tudelft | G17: Education/research | H17: Ras Lalmy (YES!Delft) | I17: Radena | K17: NO | L17: NO | M17: Sent to j.j.m.konings@tudelft.nl on 2025-09-01 | O17: =vlookup(E17,Sheet16!B:C,1,false) -> #REF!
A18: =B18&" "&F18 -> Zwanet van Lubek AMS Institute | B18: =C18&" "&D18 -> Zwanet van Lubek | C18: Zwanet | D18: van Lubek | F18: AMS Institute | G18: Education/research | H18: Freek Smoes (YES!Delft) | J18: FALSE | K18: NO | L18: NO
A19: =B19&" "&F19 -> Hanna Lucas innovationquarter | B19: =C19&" "&D19 -> Hanna Lucas | C19: Hanna | D19: Lucas | E19: hanna.lucas@innovationquarter.nl | F19: innovationquarter | G19: Mentor/Expert | H19: Radena Tsoneva (YES!Delft) | J19: FALSE | L19: Bounce
A20: =B20&" "&F20 -> Nathal van Rijn | B20: =C20&" "&D20 -> Nathal van Rijn | C20: Nathal | D20: van Rijn | G20: Startup Ecosystem | H20: Freek Smoes (YES!Delft) | K20: NO | L20: NO
A21: =B21&" "&F21 -> Maarten Cleeren | B21: =C21&" "&D21 -> Maarten Cleeren | C21: Maarten | D21: Cleeren | G21: Partner | H21: Ras Lalmy (YES!Delft) | J21: FALSE | K21: NO | L21: NO
A22: =B22&" "&F22 -> Sophie Heijenberg nosuchventures | B22: =C22&" "&D22 -> Sophie Heijenberg | C22: Sophie | D22: Heijenberg | F22: nosuchventures | G22: Investor | H22: Jan Geert van Hall (YES!Delft) | J22: FALSE | K22: YES
A23: =B23&" "&F23 -> Fabian van der Horst rabobank | B23: =C23&" "&D23 -> Fabian van der Horst | C23: Fabian | D23: van der Horst | E23: fabian.van.der.horst@rabobank.nl | F23: rabobank | G23: Partner | H23: Ras Lalmy (YES!Delft) | J23: FALSE | K23: Free | L23: Sent to fabian.van.der.horst@rabobank.nl on 2026-06-08 | N23: No longer Rabo
A24: =B24&" "&F24 -> Pascal van de Poll strategiemakers | B24: Pascal van de Poll | C24: Pascal | D24: van de Poll | E24: pascal.vandepoll@strategiemakers.nl | F24: strategiemakers | G24: Startup Ecosystem | I24: mentor | K24: no | L24: Bounce
A25: =B25&" "&F25 -> Serge Santoo thegreenvillage | B25: Serge Santoo | C25: Serge | D25: Santoo | E25: serge.santoo@thegreenvillage.org | F25: thegreenvillage | G25: Startup Ecosystem | I25: expert | K25: no | L25: Bounce
A27: =B27&" "&F27 -> boers | C27: Ward | D27: Bingley | E27: ward.bingley@boers.nl | F27: boers | G27: Partner | I27: expert | K27: ? | L27: NO
A28: =B28&" "&F28 -> Dilis Biesheuvel designsolutions | B28: Dilis Biesheuvel | C28: Dilis | D28: Biesheuvel | E28: dbiesheuvel@designsolutions.nl | F28: designsolutions | G28: Partner | I28: Old partner | K28: ? | L28: NO
A29: =B29&" "&F29 -> Merel Haverhals nen | B29: Merel Haverhals | C29: Merel | D29: Haverhals | E29: merel.haverhals@nen.nl | F29: nen | G29: Partner | K29: ? | L29: NO
A30: =B30&" "&F30 -> Chynna Falandt Rabobank | B30: Chynna Falandt | C30: Chynna | D30: Falandt | E30: Chynna.Falandt@rabobank.nl | F30: Rabobank | G30: Partner | K30: ? | L30: NO
A33: =B33&" "&F33 -> Alessandro Bozzon tudelft | B33: Alessandro Bozzon | C33: Alessandro | D33: Bozzon | E33: a.bozzon@tudelft.nl | F33: tudelft | G33: Education/research | I33: Ailixr? | K33: ? | L33: NO
A34: =B34&" "&F34 -> Ellen van Andel tudelft | B34: Ellen van Andel | C34: Ellen | D34: van Andel | E34: e.vanandel@tudelft.nl | F34: tudelft | G34: Education/research | K34: ? | L34: NO
A35: =B35&" "&F35 -> Hanieh Khodaei tudelft | B35: Hanieh Khodaei | C35: Hanieh | D35: Khodaei | E35: h.khodaei@tudelft.nl | F35: tudelft | G35: Education/research | K35: ? | L35: NO
A36: =B36&" "&F36 -> Jens Kok tudelft | B36: Jens Kok | C36: Jens | D36: Kok | E36: j.kok@tudelft.nl | F36: tudelft | G36: Education/research | K36: ? | L36: NO
A37: =B37&" "&F37 -> Daniel de Raadt vlst | B37: Daniel de Raadt | C37: Daniel | D37: de Raadt | E37: d.deraat@vlst.com | F37: vlst | G37: Partner | K37: ? | L37: NO
A38: =B38&" "&F38 -> Anastasia Bhadai Rabobank | B38: Anastasia Bhadai | C38: Anastasia | D38: Bhadai | E38: anastasia.bhadai@rabobank.nl | F38: Rabobank | G38: Partner | H38: Ras Lalmy (YES!Delft) | I38: x | K38: ? | L38: Sent to anastasia.bhadai@rabobank.nl on 2026-06-08
A39: =B39&" "&F39 -> Danny Winkel Rabobank | B39: Danny Winkel | C39: Danny | D39: Winkel | E39: danny.winkel@rabobank.nl | F39: Rabobank | G39: Partner | H39: Ras Lalmy (YES!Delft) | I39: x | K39: ? | L39: Sent to danny.winkel@rabobank.nl on 2026-06-08
A40: =B40&" "&F40 -> Evelien De Kort Rabobank | B40: Evelien De Kort | C40: Evelien | D40: De Kort | E40: Evelien.de.kort@rabobank.nl | F40: Rabobank | G40: Partner | H40: Ras Lalmy (YES!Delft) | K40: ? | L40: Sent to Evelien.de.kort@rabobank.nl on 2026-06-08
A41: =B41&" "&F41 -> Marius Hovius Rabobank | B41: Marius Hovius | C41: Marius | D41: Hovius | E41: marius.hovius@rabobank.nl | F41: Rabobank | G41: Partner | H41: Ras Lalmy (YES!Delft) | I41: x | K41: ? | L41: Sent to marius.hovius@rabobank.nl on 2026-06-08
A42: =B42&" "&F42 -> Patrick Van Der Toorn Rabobank | B42: Patrick Van Der Toorn | C42: Patrick | D42: Van Der Toorn | E42: patrick.van.der.toorn@rabobank.nl | F42: Rabobank | G42: Partner | H42: Ras Lalmy (YES!Delft) | K42: ? | L42: Sent to patrick.van.der.toorn@rabobank.nl on 2026-06-08
A43: =B43&" "&F43 -> Peter Smid rabobank | B43: Peter Smid | C43: Peter | D43: Smit | E43: peter.smit@rabobank.com | F43: rabobank | G43: Partner | H43: Ras Lalmy (YES!Delft) | K43: ? | L43: Sent to peter.smit@rabobank.com on 2026-06-08
...

Sheet MTS 2026 registrations
A1: !Data from this sheet is loaded from Project Master Sheet - MTS 2026! Registrations, DON'T EDIT THIS SHEET! | K1: =COUNTIF(K2:K500, "Marked") -> 90 | L1: Things changed in the registration sheet in MTS document so this is all fucked up now.
A2: =IFERROR(__xludf.DUMMYFUNCTION("importrange(""https://docs.google.com/spreadsheets/d/1tdVMyaSX1NOOnhLoywkFFXAlzGwYRUtaHrBX8He56SI/edit?gid=1911872096#gid=1911872096"",""Registrations!A:F"")"),"Name") -> Name | B2: =IFERROR(__xludf.DUMMYFUNCTION("""COMPUTED_VALUE"""),"Email") -> Email | C2: =IFERROR(__xludf.DUMMYFUNCTION("""COMPUTED_VALUE"""),"Company/University") -> Company/University | D2: =IFERROR(__xludf.DUMMYFUNCTION("""COMPUTED_VALUE"""),"Job title/Study") -> Job title/Study | E2: =IFERROR(__xludf.DUMMYFUNCTION("""COMPUTED_VALUE"""),"Goal of event") -> Goal of event | F2: =IFERROR(__xludf.DUMMYFUNCTION("""COMPUTED_VALUE"""),"Sectors of interest") -> Sectors of interest | G2: Used Code | H2: lookup email | I2: lookupmail | J2: Lookup used code | K2: not on our list | L2: remark
A3: =IFERROR(__xludf.DUMMYFUNCTION("""COMPUTED_VALUE"""),"Anton Schreuders") -> Anton Schreuders | B3: =IFERROR(__xludf.DUMMYFUNCTION("""COMPUTED_VALUE"""),"anton.schreuders@eao.com") -> anton.schreuders@eao.com | C3: =IFERROR(__xludf.DUMMYFUNCTION("""COMPUTED_VALUE"""),"EAO Benelux B.V.") -> EAO Benelux B.V. | D3: =IFERROR(__xludf.DUMMYFUNCTION("""COMPUTED_VALUE"""),"Applicatio Specialist machinery & ships") -> Applicatio Specialist machinery & ships | E3: =IFERROR(__xludf.DUMMYFUNCTION("""COMPUTED_VALUE"""),"new contacts") -> new contacts | F3: =IFERROR(__xludf.DUMMYFUNCTION("""COMPUTED_VALUE"""),"Maritime") -> Maritime | H3: =VLOOKUP(B3,'new total list'!E:E,1,false) -> #N/A | I3: =vlookup(A3,'new total list'!B:B,1,false) -> #N/A | K3: =IF(AND(ISNA(H3), ISNA(I3)), "Marked", "") -> Marked
A4: =IFERROR(__xludf.DUMMYFUNCTION("""COMPUTED_VALUE"""),"Paul Hendrikx") -> Paul Hendrikx | B4: =IFERROR(__xludf.DUMMYFUNCTION("""COMPUTED_VALUE"""),"paul@mangoproductdesign.com") -> paul@mangoproductdesign.com | C4: =IFERROR(__xludf.DUMMYFUNCTION("""COMPUTED_VALUE"""),"ManGo Product Design") -> ManGo Product Design | D4: =IFERROR(__xludf.DUMMYFUNCTION("""COMPUTED_VALUE"""),"CEO") -> CEO | E4: =IFERROR(__xludf.DUMMYFUNCTION("""COMPUTED_VALUE"""),"Meet the innovators of tomorrow") -> Meet the innovators of tomorrow | F4: =IFERROR(__xludf.DUMMYFUNCTION("""COMPUTED_VALUE"""),"Energy") -> Energy | H4: =VLOOKUP(B4,'new total list'!E:E,1,false) -> #N/A | I4: =vlookup(A4,'new total list'!B:B,1,false) -> #N/A | K4: =IF(AND(ISNA(H4), ISNA(I4)), "Marked", "") -> Marked
A5: =IFERROR(__xludf.DUMMYFUNCTION("""COMPUTED_VALUE"""),"Joris Roozen") -> Joris Roozen | B5: =IFERROR(__xludf.DUMMYFUNCTION("""COMPUTED_VALUE"""),"joris@jorisroozen.nl") -> joris@jorisroozen.nl | C5: =IFERROR(__xludf.DUMMYFUNCTION("""COMPUTED_VALUE"""),"Intenza Consulting & Training") -> Intenza Consulting & Training | D5: =IFERROR(__xludf.DUMMYFUNCTION("""COMPUTED_VALUE"""),"Partner") -> Partner | E5: =IFERROR(__xludf.DUMMYFUNCTION("""COMPUTED_VALUE"""),"Inspiration & Networking") -> Inspiration & Networking | F5: =IFERROR(__xludf.DUMMYFUNCTION("""COMPUTED_VALUE"""),"Energy") -> Energy | H5: =VLOOKUP(B5,'new total list'!E:E,1,false) -> #N/A | I5: =vlookup(A5,'new total list'!B:B,1,false) -> #N/A | K5: =IF(AND(ISNA(H5), ISNA(I5)), "Marked", "") -> Marked | L5: Contact Ras - potential mentor
A6: =IFERROR(__xludf.DUMMYFUNCTION("""COMPUTED_VALUE"""),"Teake Bulstra") -> Teake Bulstra | B6: =IFERROR(__xludf.DUMMYFUNCTION("""COMPUTED_VALUE"""),"teake@baatmedical.com") -> teake@baatmedical.com | C6: =IFERROR(__xludf.DUMMYFUNCTION("""COMPUTED_VALUE"""),"www.baatmedical.com") -> www.baatmedical.com | D6: =IFERROR(__xludf.DUMMYFUNCTION("""COMPUTED_VALUE"""),"new business development") -> new business development | E6: =IFERROR(__xludf.DUMMYFUNCTION("""COMPUTED_VALUE"""),"meet innovators; add value with our knowledge and experience on medical device development") -> meet innovators; add value with our knowledge and experience on medical device development | F6: =IFERROR(__xludf.DUMMYFUNCTION("""COMPUTED_VALUE"""),"manufacturing") -> manufacturing | H6: =VLOOKUP(B6,'new total list'!E:E,1,false) -> #N/A | I6: =vlookup(A6,'new total list'!B:B,1,false) -> #N/A | K6: =IF(AND(ISNA(H6), ISNA(I6)), "Marked", "") -> Marked
A7: =IFERROR(__xludf.DUMMYFUNCTION("""COMPUTED_VALUE"""),"Boudewijn Soetens") -> Boudewijn Soetens | B7: =IFERROR(__xludf.DUMMYFUNCTION("""COMPUTED_VALUE"""),"boudewijn@tekkoo.nl") -> boudewijn@tekkoo.nl | C7: =IFERROR(__xludf.DUMMYFUNCTION("""COMPUTED_VALUE"""),"Tekkoo") -> Tekkoo | D7: =IFERROR(__xludf.DUMMYFUNCTION("""COMPUTED_VALUE"""),"Senior Innovation Lead") -> Senior Innovation Lead | E7: =IFERROR(__xludf.DUMMYFUNCTION("""COMPUTED_VALUE"""),"Get to know the YesDelft ecosystem better") -> Get to know the YesDelft ecosystem better | F7: =IFERROR(__xludf.DUMMYFUNCTION("""COMPUTED_VALUE"""),"we are facilitating the BlueCity Startup Studio in Rotterdam and there is a potential to work together.") -> we are facilitating the BlueCity Startup Studio in Rotterdam and there is a potential to work together. | H7: =VLOOKUP(B7,'new total list'!E:E,1,false) -> #N/A | I7: =vlookup(A7,'new total list'!B:B,1,false) -> #N/A | K7: =IF(AND(ISNA(H7), ISNA(I7)), "Marked", "") -> Marked
A8: =IFERROR(__xludf.DUMMYFUNCTION("""COMPUTED_VALUE"""),"Katharina") -> Katharina | B8: =IFERROR(__xludf.DUMMYFUNCTION("""COMPUTED_VALUE"""),"katharina.pavlin@catalyze-group.com") -> katharina.pavlin@catalyze-group.com | C8: =IFERROR(__xludf.DUMMYFUNCTION("""COMPUTED_VALUE"""),"Catalyze BV") -> Catalyze BV | D8: =IFERROR(__xludf.DUMMYFUNCTION("""COMPUTED_VALUE"""),"Business Developer") -> Business Developer | E8: =IFERROR(__xludf.DUMMYFUNCTION("""COMPUTED_VALUE"""),"connect with startups and advice them about funding opportunities") -> connect with startups and advice them about funding opportunities | F8: =IFERROR(__xludf.DUMMYFUNCTION("""COMPUTED_VALUE"""),"Energy") -> Energy | H8: =VLOOKUP(B8,'new total list'!E:E,1,false) -> #N/A | I8: =vlookup(A8,'new total list'!B:B,1,false) -> #N/A | K8: =IF(AND(ISNA(H8), ISNA(I8)), "Marked", "") -> Marked
A9: =IFERROR(__xludf.DUMMYFUNCTION("""COMPUTED_VALUE"""),"Dymphy") -> Dymphy | B9: =IFERROR(__xludf.DUMMYFUNCTION("""COMPUTED_VALUE"""),"dymphy@baatmedical.com") -> dymphy@baatmedical.com | C9: =IFERROR(__xludf.DUMMYFUNCTION("""COMPUTED_VALUE"""),"BAAT Medical") -> BAAT Medical | D9: =IFERROR(__xludf.DUMMYFUNCTION("""COMPUTED_VALUE"""),"Business Developer") -> Business Developer | E9: =IFERROR(__xludf.DUMMYFUNCTION("""COMPUTED_VALUE"""),"Strengthen network") -> Strengthen network | F9: =IFERROR(__xludf.DUMMYFUNCTION("""COMPUTED_VALUE"""),"MedTech") -> MedTech | H9: =VLOOKUP(B9,'new total list'!E:E,1,false) -> #N/A | I9: =vlookup(A9,'new total list'!B:B,1,false) -> #N/A | K9: =IF(AND(ISNA(H9), ISNA(I9)), "Marked", "") -> Marked
A10: =IFERROR(__xludf.DUMMYFUNCTION("""COMPUTED_VALUE"""),"Jan Willem ten Dam") -> Jan Willem ten Dam | B10: =IFERROR(__xludf.DUMMYFUNCTION("""COMPUTED_VALUE"""),"j.tendam@aomb.nl") -> j.tendam@aomb.nl | C10: =IFERROR(__xludf.DUMMYFUNCTION("""COMPUTED_VALUE"""),"AOMB") -> AOMB | D10: =IFERROR(__xludf.DUMMYFUNCTION("""COMPUTED_VALUE"""),"patent attorney") -> patent attorney | E10: =IFERROR(__xludf.DUMMYFUNCTION("""COMPUTED_VALUE"""),"As an Industrial Design Engineering alumnus with friends active in YES!Delft startups") -> As an Industrial Design Engineering alumnus with friends active in YES!Delft startups | F10: =IFERROR(__xludf.DUMMYFUNCTION("""COMPUTED_VALUE"""),"I want to catch up on what happens at YES!Delft and network with new startups.") -> I want to catch up on what happens at YES!Delft and network with new startups. | H10: =VLOOKUP(B10,'new total list'!E:E,1,false) -> #N/A | I10: =vlookup(A10,'new total list'!B:B,1,false) -> #N/A | K10: =IF(AND(ISNA(H10), ISNA(I10)), "Marked", "") -> Marked
A11: =IFERROR(__xludf.DUMMYFUNCTION("""COMPUTED_VALUE"""),"Anita Lieverdink") -> Anita Lieverdink | B11: =IFERROR(__xludf.DUMMYFUNCTION("""COMPUTED_VALUE"""),"anita.lieverdink@aic4nl.nl") -> anita.lieverdink@aic4nl.nl | C11: =IFERROR(__xludf.DUMMYFUNCTION("""COMPUTED_VALUE"""),"AIC4NL") -> AIC4NL | D11: =IFERROR(__xludf.DUMMYFUNCTION("""COMPUTED_VALUE"""),"Lead AI scale-up program") -> Lead AI scale-up program | E11: =IFERROR(__xludf.DUMMYFUNCTION("""COMPUTED_VALUE"""),"scouting AI startups") -> scouting AI startups | F11: =IFERROR(__xludf.DUMMYFUNCTION("""COMPUTED_VALUE"""),"Energy") -> Energy | H11: =VLOOKUP(B11,'new total list'!E:E,1,false) -> anita.lieverdink@aic4nl.nl | I11: =vlookup(A11,'new total list'!B:B,1,false) -> Anita Lieverdink | K11: =IF(AND(ISNA(H11), ISNA(I11)), "Marked", "")
A12: =IFERROR(__xludf.DUMMYFUNCTION("""COMPUTED_VALUE"""),"Bob") -> Bob | B12: =IFERROR(__xludf.DUMMYFUNCTION("""COMPUTED_VALUE"""),"b.stassar@benedictpeax.com") -> b.stassar@benedictpeax.com | C12: =IFERROR(__xludf.DUMMYFUNCTION("""COMPUTED_VALUE"""),"Benedict Peax") -> Benedict Peax | D12: =IFERROR(__xludf.DUMMYFUNCTION("""COMPUTED_VALUE"""),"Directeur") -> Directeur | E12: =IFERROR(__xludf.DUMMYFUNCTION("""COMPUTED_VALUE"""),"Contacts") -> Contacts | F12: =IFERROR(__xludf.DUMMYFUNCTION("""COMPUTED_VALUE"""),"leads") -> leads | H12: =VLOOKUP(B12,'new total list'!E:E,1,false) -> b.stassar@benedictpeax.com | I12: =vlookup(A12,'new total list'!B:B,1,false) -> #N/A | K12: =IF(AND(ISNA(H12), ISNA(I12)), "Marked", "")
A13: =IFERROR(__xludf.DUMMYFUNCTION("""COMPUTED_VALUE"""),"Bram") -> Bram | B13: =IFERROR(__xludf.DUMMYFUNCTION("""COMPUTED_VALUE"""),"am.spitzer@pzh.nl") -> am.spitzer@pzh.nl | C13: =IFERROR(__xludf.DUMMYFUNCTION("""COMPUTED_VALUE"""),"Founded in South Holland") -> Founded in South Holland | D13: =IFERROR(__xludf.DUMMYFUNCTION("""COMPUTED_VALUE"""),"Public Lead") -> Public Lead | E13: =IFERROR(__xludf.DUMMYFUNCTION("""COMPUTED_VALUE"""),"Network") -> Network | F13: =IFERROR(__xludf.DUMMYFUNCTION("""COMPUTED_VALUE"""),"Energy") -> Energy | H13: =VLOOKUP(B13,'new total list'!E:E,1,false) -> am.spitzer@pzh.nl | I13: =vlookup(A13,'new total list'!B:B,1,false) -> #N/A | K13: =IF(AND(ISNA(H13), ISNA(I13)), "Marked", "")
A14: =IFERROR(__xludf.DUMMYFUNCTION("""COMPUTED_VALUE"""),"Freek Smoes") -> Freek Smoes | B14: =IFERROR(__xludf.DUMMYFUNCTION("""COMPUTED_VALUE"""),"freek@yesdelft.nl") -> freek@yesdelft.nl | C14: =IFERROR(__xludf.DUMMYFUNCTION("""COMPUTED_VALUE"""),"YES!Delft") -> YES!Delft | D14: =IFERROR(__xludf.DUMMYFUNCTION("""COMPUTED_VALUE"""),"Head of Incubator") -> Head of Incubator | E14: =IFERROR(__xludf.DUMMYFUNCTION("""COMPUTED_VALUE"""),"Valuable connections") -> Valuable connections | F14: =IFERROR(__xludf.DUMMYFUNCTION("""COMPUTED_VALUE"""),"​Aerospace") -> ​Aerospace | H14: =VLOOKUP(B14,'new total list'!E:E,1,false) -> freek@yesdelft.nl | I14: =vlookup(A14,'new total list'!B:B,1,false) -> Freek Smoes | K14: =IF(AND(ISNA(H14), ISNA(I14)), "Marked", "") | L14: ? | M14: moshe
A15: =IFERROR(__xludf.DUMMYFUNCTION("""COMPUTED_VALUE"""),"Danique Engelberts") -> Danique Engelberts | B15: =IFERROR(__xludf.DUMMYFUNCTION("""COMPUTED_VALUE"""),"danique@yesdelft.nl") -> danique@yesdelft.nl | C15: =IFERROR(__xludf.DUMMYFUNCTION("""COMPUTED_VALUE"""),"YES!Delft") -> YES!Delft | D15: =IFERROR(__xludf.DUMMYFUNCTION("""COMPUTED_VALUE"""),"Event Manager") -> Event Manager | E15: =IFERROR(__xludf.DUMMYFUNCTION("""COMPUTED_VALUE"""),"Succes!") -> Succes! | F15: =IFERROR(__xludf.DUMMYFUNCTION("""COMPUTED_VALUE"""),"Energy") -> Energy | H15: =VLOOKUP(B15,'new total list'!E:E,1,false) -> Danique@yesdelft.nl | I15: =vlookup(A15,'new total list'!B:B,1,false) -> #N/A | K15: =IF(AND(ISNA(H15), ISNA(I15)), "Marked", "")
A16: =IFERROR(__xludf.DUMMYFUNCTION("""COMPUTED_VALUE"""),"Fabian Groeneveld") -> Fabian Groeneveld | B16: =IFERROR(__xludf.DUMMYFUNCTION("""COMPUTED_VALUE"""),"fabian.groeneveld@rabobank.nl") -> fabian.groeneveld@rabobank.nl | C16: =IFERROR(__xludf.DUMMYFUNCTION("""COMPUTED_VALUE"""),"Rabobank") -> Rabobank | D16: =IFERROR(__xludf.DUMMYFUNCTION("""COMPUTED_VALUE"""),"Startup & Scale-up Banker") -> Startup & Scale-up Banker | E16: =IFERROR(__xludf.DUMMYFUNCTION("""COMPUTED_VALUE"""),"Network connections") -> Network connections | F16: =IFERROR(__xludf.DUMMYFUNCTION("""COMPUTED_VALUE"""),"Maritime") -> Maritime | H16: =VLOOKUP(B16,'new total list'!E:E,1,false) -> fabian.groeneveld@rabobank.nl | I16: =vlookup(A16,'new total list'!B:B,1,false) -> Fabian Groeneveld | K16: =IF(AND(ISNA(H16), ISNA(I16)), "Marked", "")
A17: =IFERROR(__xludf.DUMMYFUNCTION("""COMPUTED_VALUE"""),"Daniel Kofman") -> Daniel Kofman | B17: =IFERROR(__xludf.DUMMYFUNCTION("""COMPUTED_VALUE"""),"daniel.kofman@siemens.com") -> daniel.kofman@siemens.com | C17: =IFERROR(__xludf.DUMMYFUNCTION("""COMPUTED_VALUE"""),"Siemens Digital Industries") -> Siemens Digital Industries | D17: =IFERROR(__xludf.DUMMYFUNCTION("""COMPUTED_VALUE"""),"Education Xcelerator") -> Education Xcelerator | E17: =IFERROR(__xludf.DUMMYFUNCTION("""COMPUTED_VALUE"""),"meet interesting startus to support") -> meet interesting startus to support | F17: =IFERROR(__xludf.DUMMYFUNCTION("""COMPUTED_VALUE"""),"Dual Use") -> Dual Use | H17: =VLOOKUP(B17,'new total list'!E:E,1,false) -> daniel.kofman@siemens.com | I17: =vlookup(A17,'new total list'!B:B,1,false) -> Daniel Kofman | K17: =IF(AND(ISNA(H17), ISNA(I17)), "Marked", "")
A18: =IFERROR(__xludf.DUMMYFUNCTION("""COMPUTED_VALUE"""),"Floris Blonk") -> Floris Blonk | B18: =IFERROR(__xludf.DUMMYFUNCTION("""COMPUTED_VALUE"""),"floris.blonk@energy-innovation.nl") -> floris.blonk@energy-innovation.nl | C18: =IFERROR(__xludf.DUMMYFUNCTION("""COMPUTED_VALUE"""),"Energy Innovation NL") -> Energy Innovation NL | D18: =IFERROR(__xludf.DUMMYFUNCTION("""COMPUTED_VALUE"""),"Program Manager") -> Program Manager | E18: =IFERROR(__xludf.DUMMYFUNCTION("""COMPUTED_VALUE"""),"Scout new offshore renewable energy startups") -> Scout new offshore renewable energy startups | F18: =IFERROR(__xludf.DUMMYFUNCTION("""COMPUTED_VALUE"""),"get insight in latest developments and needs.") -> get insight in latest developments and needs. | H18: =VLOOKUP(B18,'new total list'!E:E,1,false) -> #N/A | I18: =vlookup(A18,'new total list'!B:B,1,false) -> Floris Blonk | K18: =IF(AND(ISNA(H18), ISNA(I18)), "Marked", "")
A19: =IFERROR(__xludf.DUMMYFUNCTION("""COMPUTED_VALUE"""),"Anske Plante") -> Anske Plante | B19: =IFERROR(__xludf.DUMMYFUNCTION("""COMPUTED_VALUE"""),"j.a.plante@tudelft.nl") -> j.a.plante@tudelft.nl | C19: =IFERROR(__xludf.DUMMYFUNCTION("""COMPUTED_VALUE"""),"TU Delft - Technische Universiteit Delft") -> TU Delft - Technische Universiteit Delft | D19: =IFERROR(__xludf.DUMMYFUNCTION("""COMPUTED_VALUE"""),"Accountmanager") -> Accountmanager | E19: =IFERROR(__xludf.DUMMYFUNCTION("""COMPUTED_VALUE"""),"making connections between startups and sme") -> making connections between startups and sme | F19: =IFERROR(__xludf.DUMMYFUNCTION("""COMPUTED_VALUE"""),"Energy") -> Energy | H19: =VLOOKUP(B19,'new total list'!E:E,1,false) -> j.a.plante@tudelft.nl | I19: =vlookup(A19,'new total list'!B:B,1,false) -> Anske Plante | K19: =IF(AND(ISNA(H19), ISNA(I19)), "Marked", "")
A20: =IFERROR(__xludf.DUMMYFUNCTION("""COMPUTED_VALUE"""),"Jemy Pauwels") -> Jemy Pauwels | B20: =IFERROR(__xludf.DUMMYFUNCTION("""COMPUTED_VALUE"""),"jemy.pauwels@demcon.com") -> jemy.pauwels@demcon.com | C20: =IFERROR(__xludf.DUMMYFUNCTION("""COMPUTED_VALUE"""),"UDT TechFund by VDL & DEMCON") -> UDT TechFund by VDL & DEMCON | D20: =IFERROR(__xludf.DUMMYFUNCTION("""COMPUTED_VALUE"""),"Investment Director") -> Investment Director | E20: =IFERROR(__xludf.DUMMYFUNCTION("""COMPUTED_VALUE"""),"Investments") -> Investments | F20: =IFERROR(__xludf.DUMMYFUNCTION("""COMPUTED_VALUE"""),"Maritime") -> Maritime | H20: =VLOOKUP(B20,'new total list'!E:E,1,false) -> jemy.pauwels@demcon.com | I20: =vlookup(A20,'new total list'!B:B,1,false) -> Jemy Pauwels | K20: =IF(AND(ISNA(H20), ISNA(I20)), "Marked", "")
A21: =IFERROR(__xludf.DUMMYFUNCTION("""COMPUTED_VALUE"""),"brian stout") -> brian stout | B21: =IFERROR(__xludf.DUMMYFUNCTION("""COMPUTED_VALUE"""),"brian.stout@ziggo.nl") -> brian.stout@ziggo.nl | C21: =IFERROR(__xludf.DUMMYFUNCTION("""COMPUTED_VALUE"""),"Stout Managament Services BV") -> Stout Managament Services BV | D21: =IFERROR(__xludf.DUMMYFUNCTION("""COMPUTED_VALUE"""),"Directeur") -> Directeur | E21: =IFERROR(__xludf.DUMMYFUNCTION("""COMPUTED_VALUE"""),"To understand what new exciting ideas are there and how I can contribute as a mentor") -> To understand what new exciting ideas are there and how I can contribute as a mentor | F21: =IFERROR(__xludf.DUMMYFUNCTION("""COMPUTED_VALUE"""),"Dual Use") -> Dual Use | H21: =VLOOKUP(B21,'new total list'!E:E,1,false) -> brian.stout@ziggo.nl | I21: =vlookup(A21,'new total list'!B:B,1,false) -> Brian Stout | K21: =IF(AND(ISNA(H21), ISNA(I21)), "Marked", "")
A22: =IFERROR(__xludf.DUMMYFUNCTION("""COMPUTED_VALUE"""),"Tomba Paagman") -> Tomba Paagman | B22: =IFERROR(__xludf.DUMMYFUNCTION("""COMPUTED_VALUE"""),"tomba.paagman@campusatsea.nl") -> tomba.paagman@campusatsea.nl | C22: =IFERROR(__xludf.DUMMYFUNCTION("""COMPUTED_VALUE"""),"Campus@Sea") -> Campus@Sea | D22: =IFERROR(__xludf.DUMMYFUNCTION("""COMPUTED_VALUE"""),"Junior Project Manager") -> Junior Project Manager | E22: =IFERROR(__xludf.DUMMYFUNCTION("""COMPUTED_VALUE"""),"Learning the new generation of innovators") -> Learning the new generation of innovators | F22: =IFERROR(__xludf.DUMMYFUNCTION("""COMPUTED_VALUE"""),"Maritime") -> Maritime | H22: =VLOOKUP(B22,'new total list'!E:E,1,false) -> #N/A | I22: =vlookup(A22,'new total list'!B:B,1,false) -> #N/A | K22: =IF(AND(ISNA(H22), ISNA(I22)), "Marked", "") -> Marked
A23: =IFERROR(__xludf.DUMMYFUNCTION("""COMPUTED_VALUE"""),"Maarten van der Elst") -> Maarten van der Elst | B23: =IFERROR(__xludf.DUMMYFUNCTION("""COMPUTED_VALUE"""),"m.vanderelst@tudelft.nl") -> m.vanderelst@tudelft.nl | C23: =IFERROR(__xludf.DUMMYFUNCTION("""COMPUTED_VALUE"""),"Delft University of Technology") -> Delft University of Technology | D23: =IFERROR(__xludf.DUMMYFUNCTION("""COMPUTED_VALUE"""),"Prof dr") -> Prof dr | E23: =IFERROR(__xludf.DUMMYFUNCTION("""COMPUTED_VALUE"""),"To see what is new in healthtech") -> To see what is new in healthtech | F23: =IFERROR(__xludf.DUMMYFUNCTION("""COMPUTED_VALUE"""),"MedTech") -> MedTech | H23: =VLOOKUP(B23,'new total list'!E:E,1,false) -> M.vanderElst@tudelft.nl | I23: =vlookup(A23,'new total list'!B:B,1,false) -> Maarten van der Elst | K23: =IF(AND(ISNA(H23), ISNA(I23)), "Marked", "")
A24: =IFERROR(__xludf.DUMMYFUNCTION("""COMPUTED_VALUE"""),"Joris Meijaard") -> Joris Meijaard | B24: =IFERROR(__xludf.DUMMYFUNCTION("""COMPUTED_VALUE"""),"meijaard@rsm.nl") -> meijaard@rsm.nl | C24: =IFERROR(__xludf.DUMMYFUNCTION("""COMPUTED_VALUE"""),"RSM/MIR/Yes!Delft") -> RSM/MIR/Yes!Delft | D24: =IFERROR(__xludf.DUMMYFUNCTION("""COMPUTED_VALUE"""),"Academic director") -> Academic director | E24: =IFERROR(__xludf.DUMMYFUNCTION("""COMPUTED_VALUE"""),"Inspiration") -> Inspiration | F24: =IFERROR(__xludf.DUMMYFUNCTION("""COMPUTED_VALUE"""),"​Aerospace") -> ​Aerospace | H24: =VLOOKUP(B24,'new total list'!E:E,1,false) -> meijaard@rsm.nl | I24: =vlookup(A24,'new total list'!B:B,1,false) -> Joris Meijaard | K24: =IF(AND(ISNA(H24), ISNA(I24)), "Marked", "")
A25: =IFERROR(__xludf.DUMMYFUNCTION("""COMPUTED_VALUE"""),"Philip Hess") -> Philip Hess | B25: =IFERROR(__xludf.DUMMYFUNCTION("""COMPUTED_VALUE"""),"p.hess@rotterdamfactoring.nl") -> p.hess@rotterdamfactoring.nl | C25: =IFERROR(__xludf.DUMMYFUNCTION("""COMPUTED_VALUE"""),"Rotterdam Factoring") -> Rotterdam Factoring | D25: =IFERROR(__xludf.DUMMYFUNCTION("""COMPUTED_VALUE"""),"CEO") -> CEO | E25: =IFERROR(__xludf.DUMMYFUNCTION("""COMPUTED_VALUE"""),"Connections and ideas") -> Connections and ideas | F25: =IFERROR(__xludf.DUMMYFUNCTION("""COMPUTED_VALUE"""),"Energy") -> Energy | H25: =VLOOKUP(B25,'new total list'!E:E,1,false) -> p.hess@rotterdamfactoring.nl | I25: =vlookup(A25,'new total list'!B:B,1,false) -> Philip Hess | K25: =IF(AND(ISNA(H25), ISNA(I25)), "Marked", "")
A26: =IFERROR(__xludf.DUMMYFUNCTION("""COMPUTED_VALUE"""),"Loet Rummenie") -> Loet Rummenie | B26: =IFERROR(__xludf.DUMMYFUNCTION("""COMPUTED_VALUE"""),"loet.rummenie@hiceu.com") -> loet.rummenie@hiceu.com | C26: =IFERROR(__xludf.DUMMYFUNCTION("""COMPUTED_VALUE"""),"HIC") -> HIC | D26: =IFERROR(__xludf.DUMMYFUNCTION("""COMPUTED_VALUE"""),"Managing Director") -> Managing Director | E26: =IFERROR(__xludf.DUMMYFUNCTION("""COMPUTED_VALUE"""),"network") -> network | F26: =IFERROR(__xludf.DUMMYFUNCTION("""COMPUTED_VALUE"""),"Energy") -> Energy | H26: =VLOOKUP(B26,'new total list'!E:E,1,false) -> loet.rummenie@hiceu.com | I26: =vlookup(A26,'new total list'!B:B,1,false) -> Loet Rummenie | K26: =IF(AND(ISNA(H26), ISNA(I26)), "Marked", "")
A27: =IFERROR(__xludf.DUMMYFUNCTION("""COMPUTED_VALUE"""),"Marlies Lukkes") -> Marlies Lukkes | B27: =IFERROR(__xludf.DUMMYFUNCTION("""COMPUTED_VALUE"""),"m.lukkes@shell.com") -> m.lukkes@shell.com | C27: =IFERROR(__xludf.DUMMYFUNCTION("""COMPUTED_VALUE"""),"Shell") -> Shell | D27: =IFERROR(__xludf.DUMMYFUNCTION("""COMPUTED_VALUE"""),"Commercial partnership manager") -> Commercial partnership manager | E27: =IFERROR(__xludf.DUMMYFUNCTION("""COMPUTED_VALUE"""),"connect with startups and wider ecosystem") -> connect with startups and wider ecosystem | F27: =IFERROR(__xludf.DUMMYFUNCTION("""COMPUTED_VALUE"""),"Maritime") -> Maritime | H27: =VLOOKUP(B27,'new total list'!E:E,1,false) -> m.lukkes@shell.com | I27: =vlookup(A27,'new total list'!B:B,1,false) -> Marlies Lukkes | K27: =IF(AND(ISNA(H27), ISNA(I27)), "Marked", "")
A28: =IFERROR(__xludf.DUMMYFUNCTION("""COMPUTED_VALUE"""),"Jelle Post") -> Jelle Post | B28: =IFERROR(__xludf.DUMMYFUNCTION("""COMPUTED_VALUE"""),"jelle.post@tudelft.nl") -> jelle.post@tudelft.nl | C28: =IFERROR(__xludf.DUMMYFUNCTION("""COMPUTED_VALUE"""),"Delft Enterprises") -> Delft Enterprises | D28: =IFERROR(__xludf.DUMMYFUNCTION("""COMPUTED_VALUE"""),"Investment Manager") -> Investment Manager | E28: =IFERROR(__xludf.DUMMYFUNCTION("""COMPUTED_VALUE"""),"Supporting our spin-offs & network") -> Supporting our spin-offs & network | F28: =IFERROR(__xludf.DUMMYFUNCTION("""COMPUTED_VALUE"""),"​Future of Compute") -> ​Future of Compute | H28: =VLOOKUP(B28,'new total list'!E:E,1,false) -> jelle.post@tudelft.nl | I28: =vlookup(A28,'new total list'!B:B,1,false) -> Jelle Post | K28: =IF(AND(ISNA(H28), ISNA(I28)), "Marked", "")
A29: =IFERROR(__xludf.DUMMYFUNCTION("""COMPUTED_VALUE"""),"richard. van der Vegt") -> richard. van der Vegt | B29: =IFERROR(__xludf.DUMMYFUNCTION("""COMPUTED_VALUE"""),"rg.vd.vegt@mindef.nl") -> rg.vd.vegt@mindef.nl | C29: =IFERROR(__xludf.DUMMYFUNCTION("""COMPUTED_VALUE"""),"TNO DSS") -> TNO DSS | D29: =IFERROR(__xludf.DUMMYFUNCTION("""COMPUTED_VALUE"""),"Business Manager") -> Business Manager | E29: =IFERROR(__xludf.DUMMYFUNCTION("""COMPUTED_VALUE"""),"learning") -> learning | F29: =IFERROR(__xludf.DUMMYFUNCTION("""COMPUTED_VALUE"""),"Dual Use") -> Dual Use | H29: =VLOOKUP(B29,'new total list'!E:E,1,false) -> rg.vd.vegt@mindef.nl | I29: =vlookup(A29,'new total list'!B:B,1,false) -> #N/A | K29: =IF(AND(ISNA(H29), ISNA(I29)), "Marked", "")
A30: =IFERROR(__xludf.DUMMYFUNCTION("""COMPUTED_VALUE"""),"Sander Peltenburg") -> Sander Peltenburg | B30: =IFERROR(__xludf.DUMMYFUNCTION("""COMPUTED_VALUE"""),"sander.peltenburg@rabobank.nl") -> sander.peltenburg@rabobank.nl | C30: =IFERROR(__xludf.DUMMYFUNCTION("""COMPUTED_VALUE"""),"Rabobank") -> Rabobank | D30: =IFERROR(__xludf.DUMMYFUNCTION("""COMPUTED_VALUE"""),"start and scaleup banker") -> start and scaleup banker | E30: =IFERROR(__xludf.DUMMYFUNCTION("""COMPUTED_VALUE"""),"meet the startups") -> meet the startups | F30: =IFERROR(__xludf.DUMMYFUNCTION("""COMPUTED_VALUE"""),"Energy") -> Energy | H30: =VLOOKUP(B30,'new total list'!E:E,1,false) -> sander.peltenburg@rabobank.nl | I30: =vlookup(A30,'new total list'!B:B,1,false) -> Sander Peltenburg | K30: =IF(AND(ISNA(H30), ISNA(I30)), "Marked", "")
A31: =IFERROR(__xludf.DUMMYFUNCTION("""COMPUTED_VALUE"""),"renze blokland") -> renze blokland | B31: =IFERROR(__xludf.DUMMYFUNCTION("""COMPUTED_VALUE"""),"renze.blokland@fme.nl") -> renze.blokland@fme.nl | C31: =IFERROR(__xludf.DUMMYFUNCTION("""COMPUTED_VALUE"""),"FME") -> FME | D31: =IFERROR(__xludf.DUMMYFUNCTION("""COMPUTED_VALUE"""),"funding advisor") -> funding advisor | E31: =IFERROR(__xludf.DUMMYFUNCTION("""COMPUTED_VALUE"""),"connections with start/scale ups") -> connections with start/scale ups | F31: =IFERROR(__xludf.DUMMYFUNCTION("""COMPUTED_VALUE"""),"​Aerospace") -> ​Aerospace | H31: =VLOOKUP(B31,'new total list'!E:E,1,false) -> renze.blokland@fme.nl | I31: =vlookup(A31,'new total list'!B:B,1,false) -> Renze Blokland | K31: =IF(AND(ISNA(H31), ISNA(I31)), "Marked", "")
A32: =IFERROR(__xludf.DUMMYFUNCTION("""COMPUTED_VALUE"""),"Nina Donker") -> Nina Donker | B32: =IFERROR(__xludf.DUMMYFUNCTION("""COMPUTED_VALUE"""),"nina@capitaltvc.com") -> nina@capitaltvc.com | C32: =IFERROR(__xludf.DUMMYFUNCTION("""COMPUTED_VALUE"""),"CapitalT") -> CapitalT | D32: =IFERROR(__xludf.DUMMYFUNCTION("""COMPUTED_VALUE"""),"Investment Associate") -> Investment Associate | E32: =IFERROR(__xludf.DUMMYFUNCTION("""COMPUTED_VALUE"""),"Network") -> Network | F32: =IFERROR(__xludf.DUMMYFUNCTION("""COMPUTED_VALUE"""),"Energy") -> Energy | H32: =VLOOKUP(B32,'new total list'!E:E,1,false) -> nina@capitaltvc.com | I32: =vlookup(A32,'new total list'!B:B,1,false) -> Nina Donker | K32: =IF(AND(ISNA(H32), ISNA(I32)), "Marked", "")
A33: =IFERROR(__xludf.DUMMYFUNCTION("""COMPUTED_VALUE"""),"Aman Jindal") -> Aman Jindal | B33: =IFERROR(__xludf.DUMMYFUNCTION("""COMPUTED_VALUE"""),"aman.jindal@denoize.com") -> aman.jindal@denoize.com | C33: =IFERROR(__xludf.DUMMYFUNCTION("""COMPUTED_VALUE"""),"DeNoize B.V.") -> DeNoize B.V. | D33: =IFERROR(__xludf.DUMMYFUNCTION("""COMPUTED_VALUE"""),"CEO") -> CEO | E33: =IFERROR(__xludf.DUMMYFUNCTION("""COMPUTED_VALUE"""),"Network") -> Network | F33: =IFERROR(__xludf.DUMMYFUNCTION("""COMPUTED_VALUE"""),"Dual Use") -> Dual Use | H33: =VLOOKUP(B33,'new total list'!E:E,1,false) -> aman.jindal@denoize.com | I33: =vlookup(A33,'new total list'!B:B,1,false) -> Aman Jindal | K33: =IF(AND(ISNA(H33), ISNA(I33)), "Marked", "")
A34: =IFERROR(__xludf.DUMMYFUNCTION("""COMPUTED_VALUE"""),"Simone van Schijndel") -> Simone van Schijndel | B34: =IFERROR(__xludf.DUMMYFUNCTION("""COMPUTED_VALUE"""),"s.a.h.vanschijndel@tudelft.nl") -> s.a.h.vanschijndel@tudelft.nl | C34: =IFERROR(__xludf.DUMMYFUNCTION("""COMPUTED_VALUE"""),"TU Delft") -> TU Delft | D34: =IFERROR(__xludf.DUMMYFUNCTION("""COMPUTED_VALUE"""),"Head Program & Partnership Development") -> Head Program & Partnership Development | E34: =IFERROR(__xludf.DUMMYFUNCTION("""COMPUTED_VALUE"""),"get to know the startups in the TU Delft ecosystem") -> get to know the startups in the TU Delft ecosystem | F34: =IFERROR(__xludf.DUMMYFUNCTION("""COMPUTED_VALUE"""),"Maritime") -> Maritime | H34: =VLOOKUP(B34,'new total list'!E:E,1,false) -> s.a.h.vanschijndel@tudelft.nl | I34: =vlookup(A34,'new total list'!B:B,1,false) -> Simone van Schijndel | K34: =IF(AND(ISNA(H34), ISNA(I34)), "Marked", "")
A35: =IFERROR(__xludf.DUMMYFUNCTION("""COMPUTED_VALUE"""),"Jacqueline Papendrecht") -> Jacqueline Papendrecht | B35: =IFERROR(__xludf.DUMMYFUNCTION("""COMPUTED_VALUE"""),"j.papendrecht@tudelft.nl") -> j.papendrecht@tudelft.nl | C35: =IFERROR(__xludf.DUMMYFUNCTION("""COMPUTED_VALUE"""),"TU DELFT CAMPUS") -> TU DELFT CAMPUS | D35: =IFERROR(__xludf.DUMMYFUNCTION("""COMPUTED_VALUE"""),"accountmanager") -> accountmanager | E35: =IFERROR(__xludf.DUMMYFUNCTION("""COMPUTED_VALUE"""),"networking") -> networking | F35: =IFERROR(__xludf.DUMMYFUNCTION("""COMPUTED_VALUE"""),"Dual Use") -> Dual Use | H35: =VLOOKUP(B35,'new total list'!E:E,1,false) -> j.papendrecht@tudelft.nl | I35: =vlookup(A35,'new total list'!B:B,1,false) -> Jacqueline Papendrecht | K35: =IF(AND(ISNA(H35), ISNA(I35)), "Marked", "")
A36: =IFERROR(__xludf.DUMMYFUNCTION("""COMPUTED_VALUE"""),"Luuk Mur") -> Luuk Mur | B36: =IFERROR(__xludf.DUMMYFUNCTION("""COMPUTED_VALUE"""),"l.c.mur@tudelft.nl") -> l.c.mur@tudelft.nl | C36: =IFERROR(__xludf.DUMMYFUNCTION("""COMPUTED_VALUE"""),"TU Delft") -> TU Delft | D36: =IFERROR(__xludf.DUMMYFUNCTION("""COMPUTED_VALUE"""),"Policy Advisor") -> Policy Advisor | E36: =IFERROR(__xludf.DUMMYFUNCTION("""COMPUTED_VALUE"""),"Obtain deeper insights into how TU Delft can better support the development of startups") -> Obtain deeper insights into how TU Delft can better support the development of startups | F36: =IFERROR(__xludf.DUMMYFUNCTION("""COMPUTED_VALUE"""),"​Aerospace") -> ​Aerospace | H36: =VLOOKUP(B36,'new total list'!E:E,1,false) -> l.c.mur@tudelft.nl | I36: =vlookup(A36,'new total list'!B:B,1,false) -> Luuk Mur | K36: =IF(AND(ISNA(H36), ISNA(I36)), "Marked", "")
A37: =IFERROR(__xludf.DUMMYFUNCTION("""COMPUTED_VALUE"""),"Sander Vroom") -> Sander Vroom | B37: =IFERROR(__xludf.DUMMYFUNCTION("""COMPUTED_VALUE"""),"sandervroom@gmail.com") -> sandervroom@gmail.com | C37: =IFERROR(__xludf.DUMMYFUNCTION("""COMPUTED_VALUE"""),"Rabobank") -> Rabobank | D37: =IFERROR(__xludf.DUMMYFUNCTION("""COMPUTED_VALUE"""),"Business Development Manager") -> Business Development Manager | E37: =IFERROR(__xludf.DUMMYFUNCTION("""COMPUTED_VALUE"""),"New contacts within foodsystem-") -> New contacts within foodsystem- | F37: =IFERROR(__xludf.DUMMYFUNCTION("""COMPUTED_VALUE"""),"agtech- and energytransition. And catching up with acquaintances.") -> agtech- and energytransition. And catching up with acquaintances. | H37: =VLOOKUP(B37,'new total list'!E:E,1,false) -> #N/A | I37: =vlookup(A37,'new total list'!B:B,1,false) -> Sander Vroom | K37: =IF(AND(ISNA(H37), ISNA(I37)), "Marked", "")
A38: =IFERROR(__xludf.DUMMYFUNCTION("""COMPUTED_VALUE"""),"sjoerd mol") -> sjoerd mol | B38: =IFERROR(__xludf.DUMMYFUNCTION("""COMPUTED_VALUE"""),"mol@benvalor.com") -> mol@benvalor.com | C38: =IFERROR(__xludf.DUMMYFUNCTION("""COMPUTED_VALUE"""),"Benvalor") -> Benvalor | D38: =IFERROR(__xludf.DUMMYFUNCTION("""COMPUTED_VALUE"""),"Partner") -> Partner | E38: =IFERROR(__xludf.DUMMYFUNCTION("""COMPUTED_VALUE"""),"Meeting interesting startups") -> Meeting interesting startups | F38: =IFERROR(__xludf.DUMMYFUNCTION("""COMPUTED_VALUE"""),"​Future of Compute") -> ​Future of Compute | H38: =VLOOKUP(B38,'new total list'!E:E,1,false) -> mol@benvalor.com | I38: =vlookup(A38,'new total list'!B:B,1,false) -> Sjoerd Mol | K38: =IF(AND(ISNA(H38), ISNA(I38)), "Marked", "")
A39: =IFERROR(__xludf.DUMMYFUNCTION("""COMPUTED_VALUE"""),"Kirsten Ruiter") -> Kirsten Ruiter | B39: =IFERROR(__xludf.DUMMYFUNCTION("""COMPUTED_VALUE"""),"kirsten.ruiter@buccaneerdelft.com") -> kirsten.ruiter@buccaneerdelft.com | C39: =IFERROR(__xludf.DUMMYFUNCTION("""COMPUTED_VALUE"""),"Buccaneer Delft") -> Buccaneer Delft | D39: =IFERROR(__xludf.DUMMYFUNCTION("""COMPUTED_VALUE"""),"Managing Director") -> Managing Director | E39: =IFERROR(__xludf.DUMMYFUNCTION("""COMPUTED_VALUE"""),"Meeting new startups") -> Meeting new startups | F39: =IFERROR(__xludf.DUMMYFUNCTION("""COMPUTED_VALUE"""),"seeing innovations") -> seeing innovations | H39: =VLOOKUP(B39,'new total list'!E:E,1,false) -> kirsten.ruiter@buccaneerdelft.com | I39: =vlookup(A39,'new total list'!B:B,1,false) -> Kirsten Ruiter | K39: =IF(AND(ISNA(H39), ISNA(I39)), "Marked", "")
A40: =IFERROR(__xludf.DUMMYFUNCTION("""COMPUTED_VALUE"""),"Henk van Groen") -> Henk van Groen | B40: =IFERROR(__xludf.DUMMYFUNCTION("""COMPUTED_VALUE"""),"henk@percivalparticipations.com") -> henk@percivalparticipations.com | C40: =IFERROR(__xludf.DUMMYFUNCTION("""COMPUTED_VALUE"""),"Percival Participations BV") -> Percival Participations BV | D40: =IFERROR(__xludf.DUMMYFUNCTION("""COMPUTED_VALUE"""),"Director") -> Director | E40: =IFERROR(__xludf.DUMMYFUNCTION("""COMPUTED_VALUE"""),"Ideas") -> Ideas | F40: =IFERROR(__xludf.DUMMYFUNCTION("""COMPUTED_VALUE"""),"Energy") -> Energy | H40: =VLOOKUP(B40,'new total list'!E:E,1,false) -> #N/A | I40: =vlookup(A40,'new total list'!B:B,1,false) -> Henk van Groen | K40: =IF(AND(ISNA(H40), ISNA(I40)), "Marked", "")
...

Sheet invite july
